Workbook
Name charFracC: 'General Information'!$L$12
Name FuelCalorific: 'Calorific values'!$B$3:$M$91
Name fuelFracC: 'General Information'!$L$23
Name version: Lists!$N$1
Name WindConditions: Lists!$A$3:$B$8

Sheet General Information
B1: Water Boiling Test - General Information | H1: ="Version " &version -> Version 4.2.3
B2: Test & stove description | H2: Fuel description
B3: Name of Tester(s) | H3: Your general description
B4: Test Number or Code | H4: Fuel type | J4: 1
B5: Test Dates | H5: Fuel description | J5: 1
B6: Test Year | H6: Average length (cm)
B7: Test Location | H7: Cross-sectional dimensions (cm x cm)
B8: Replicate Test Number | H8: Default values (looked up)
B9: Altitude/Elevation (m) | H9: Gross calorific value | L9: =VLOOKUP(J4,FuelCalorific,8,FALSE) -> 0 | M9: HHV, kJ/kg
B10: Stove Type/Model | H10: Net calorific value | L10: =VLOOKUP(J4,FuelCalorific,10,FALSE) -> 0 | M10: LHV,kJ/kg
B11: Manufactured by | H11: Char calorific value | L11: =VLOOKUP(J4,FuelCalorific,11,FALSE) -> 0 | M11: LHV,kJ/kg
B12: Description and Notes | H12: Char carbon content | L12: ='Calorific values'!M8 -> 0.95 | M12: by mass
H14: If possible, enter a calorific value from measurements of local fuel below.
I15: Check box if you have a measured calorific value
B16: Description of Pot(s)
H17: Measured gross calorific value | M17: HHV measured, kJ/kg
B18: Ambient conditions | H18: Measured net calorific value | M18: LHV, kJ/kg
B19: Air relative humidity (%) | H19: Assumed net calorific value | L19: =IF(ISBLANK(L18),MAX(L17-1320,0),L18) -> 0 | M19: LHV, kJ/kg
B20: Local boiling point (C) | H20: Values to be used for tests
B21: Emission testing | H21: Gross calorific value | L21: =IF(ISBLANK(H15),L9,L17) -> 0 | M21: HHV, kJ/kg
B22: Atmospheric P (kPa) | H22: Net calorific value | L22: =IF(ISBLANK(H15),L10,L19) -> 0 | M22: LHV, kJ/kg
B23: Pitot delta-P | H23: Fuel carbon content | L23: =VLOOKUP(J4,FuelCalorific,12,FALSE) -> 0 | M23: by mass | O23: =fuelFracC -> 0
B24: Hood flow rate (m3/hr) | H24: Description of firestarter (e.g. paper, fluid) and small wood or kindling
H25: (note: Kindling should be weighed and reported with wood)
B26: Notes or description about stove or operation not included elsewhere on this form
B32: Description of operation during the high-power test | G32: Description of operation during the simmering test
B33: How is fire started? | G33: How is fire started?
B38: When do you add new fuel to the fire? | G38: When do you add new fuel to the fire?
B42: How much fuel do you add at one time? | G42: How much fuel do you add at one time?
B46: How often do you feed the fire without adding fuel (e.g. push sticks)? | G46: How often do you feed the fire without adding fuel (e.g. push sticks)?
B50: Do you control the air above or below the fire? If so, what do you do? | G50: Do you control the air above or below the fire? If so, what do you do?

Sheet Test Entry
A1: Water Boiling Test - Test Entry Form | D1: ="Version " &version -> Version 4.2.3
A2: These values are not linked to the Test sheets. This sheet is provided so you can print an easy data entry form. You will have to enter these values in each Test sheet to obtain the calculations.
A3: Air Temperature | I3: Name of Testers
A5: Wind Conditions | I5: Date
I6: Stove Type/Model
A7: Fuel Dimensions | I7: Test Number
A9: Moisture Content (wet basis) | I9: Location
I11: Fuel Type
A13: Dry Weight Pot 1 | I13: Notes
A14: Dry Weight Pot 2
A15: Dry Weight Pot 3
A16: Dry Weight Pot 4
A18: Weight Container for Char
A20: Local Boiling Point *
A21: * enter on General Information
A23: Background CO2 (ppm)**
A25: Background CO (ppm)**
A27: Background PM (ug/m3)**
A28: ** For emission testing only
C29: Cold Start | H29: Hot Start | M29: Simmer
C30: Start | E30: End | H30: Start | J30: End | M30: Start | O30: End
A32: Time
A34: Weight of Fuel
A36: Water Temperature, Pot 1
A37: Water Temperature, Pot 2
A38: Water Temperature, Pot 3
A39: Water Temperature, Pot 4
A41: Weight of Pot 1 with water
A42: Weight of Pot 2 with water
A43: Weight of Pot 3 with water
A44: Weight of Pot 4 with water
A46: Fire Starting Materials
A48: Average CO2 (ppm)
... A54: Average Duct Temperature

Sheet Test-1
A2: ="WATER BOILING TEST - VERSION "&version&" - TEST #1" -> WATER BOILING TEST - VERSION 4.2.3 - TEST #1 | U2: ="TEST #1 "&D7 -> TEST #1 | W2: COLD START HIGH POWER | AE2: HOT START HIGH POWER (OPTIONAL) | AL2: SIMMER TEST
B3: DATA AND CALCULATION FORM (for one to four pots)* | W3: Start | AA3: Finish: when | AE3: Start | AI3: Finish: when | AL3: Start | AP3: Finish: 45 min
B4: Shaded cells and arrows require user input; unshaded cells automatically display outputs | AA4: Pot #1 boils | AI4: Pot #1 boils
B5: Qualitative data | U5: Measurements | V5: Units | W5: data | X5: label | AA5: data | AB5: label | AE5: data | AF5: label | AI5: data | AJ5: label | AL5: data | AM5: label | AP5: data | AQ5: label
B6: Name(s) of Tester(s) | M6: gray: efficiency | U6: Time (in 24 hour form) | V6: hr:min | X6: tci | AB6: tcf | AF6: thi | AJ6: thf | AM6: tsi | AQ6: tsf
B7: Test Number | M7: blue: emissions | U7: Weight of fuel | V7: g | X7: fci | AB7: fcf | AF7: fhi | AJ7: fhf | AM7: fsi | AQ7: fsf
B8: Date | M8: pink: error, missing input | U8: Water temperature, Pot # 1 | V8: ºC | X8: T1ci | AB8: T1cf | AF8: T1hi | AJ8: T1hf | AM8: T1si | AQ8: T1sf
B9: Location | D9: ='General Information'!C7 -> 0 | U9: Water temperature, Pot # 2 | V9: ºC | X9: T2ci | AB9: T2cf | AF9: T2hi | AJ9: T2hf | AM9: T2si | AQ9: T2sf
B10: Stove type/model | D10: ='General Information'!C10 -> 0 | U10: Water temperature, Pot # 3 | V10: ºC | X10: T3ci | AB10: T3cf | AF10: T3hi | AJ10: T3hf | AM10: T3si | AQ10: T3sf
B11: Type of fuel | D11: ='General Information'!J3 -> 0 | U11: Water temperature, Pot # 4 | V11: ºC | X11: T4ci | AB11: T4cf | AF11: T4hi | AJ11: T4hf | AM11: T4si | AQ11: T4sf
U12: Weight of Pot # 1 with water | V12: g | X12: P1ci | AB12: P1cf | AF12: P1hi | AJ12: P1hf | AM12: P1si | AQ12: P1sf
B13: Initial Test Conditions | U13: Weight of Pot # 2 with water | V13: g | X13: P2ci | AB13: P2cf | AF13: P2hi | AJ13: P2hf | AM13: P2si | AQ13: P2sf
B14: Data | E14: value | G14: units | I14: label | K14: Data | N14: value | P14: units | R14: label | U14: Weight of Pot # 3 with water | V14: g | X14: P3ci | AB14: P3cf | AF14: P3hi | AJ14: P3hf | AM14: P3si | AQ14: P3sf
B15: Air temperature | G15: ºC | K15: Dry weight of Pot # 1 (grams) | P15: g | R15: P1 | U15: Weight of Pot # 4 with water | V15: g | X15: P4ci | AB15: P4cf | AF15: P4hi | AJ15: P4hf | AM15: P4si | AQ15: P4sf
B16: Wind conditions | E16: 1 | K16: Dry weight of Pot # 2 (grams) | P16: g | R16: P2 | U16: Fire-starting materials (if any) | V16: --
B17: Fuel dimensions | K17: Dry weight of Pot # 3 (grams) | P17: g | R17: P3 | U17: Weight of charcoal+container | V17: g | AB17: cc | AI17: =AA17 -> 0 | AJ17: ch | AQ17: cs
B18: Fuel moisture content (wet basis) | G18: % | I18: MC | K18: Dry weight of Pot # 4 (grams) | P18: g | R18: P4 | U18: Average CO2 | V18: ppm | AB18: CO2c | AJ18: CO2h | AQ18: CO2s
B19: Gross calorific value (dry fuel) | E19: ='General Information'!L21 -> 0 | G19: kJ/kg | I19: HHV | K19: Weight of container for char (grams) | P19: g | R19: k | U19: Average CO | V19: ppm | Z19: 10 | AB19: COc | AJ19: COh | AQ19: COs
B20: Net calorific value (dry fuel) | E20: ='General Information'!L22 -> 0 | G20: kJ/kg | I20: LHV | K20: Local boiling point | N20: ='General Information'!C20 -> 0 | P20: ºC | R20: Tb | U20: Average PM | V20: ug/m3 | AB20: PMc | AJ20: PMh | AQ20: PMs
B21: Effective calorific value | K21: Background concentrations: CO2 | P21: ppm | R21: CO2,b | U21: Average Duct Temperature | V21: ºC | AB21: Tcd | AJ21: Thd | AQ21: Tsd
B22: (accounting for fuel moisture) | E22: =E20*(1-E18)-(E18*((N20-E15)*4.2+2260)) -> 0 | G22: kJ/kg | I22: EHV | M22: CO | P22: ppm | R22: CO,b | U22: Total CO2 (if available) | V22: g | AB22: mCO2,c | AJ22: mCO2,h | AQ22: mCO2,s
B23: Char calorific value | E23: ='General Information'!L11 -> 0 | G23: kJ/kg | M23: PM | P23: ug/m3 | R23: PM,b | U23: Total CO (if available) | V23: g | Z23: 10 | AB23: mCO,c | AJ23: mCO,h | AQ23: mCO,s
U24: Total PM (if available) | V24: g | AB24: mPM,c | AJ24: mPM,h | AQ24: mPM,s
B25: Notes about this test:
W26: COLD START | AA26: HOT START | AE26: SIMMER TEST (CALCULATIONS DIFFER FROM HIGH POWER TEST)
U27: Calculations/Results | V27: Units | W27: data | X27: label | AA27: data | AB27: label | AE27: Calculations/Results | AM27: Units | AP27: data | AQ27: label
U28: Fuel consumed (moist) | V28: g | W28: =W7-AA7 -> 0 | X28: fcm | AA28: =AE7-AI7 -> 0 | AB28: fhm | AE28: Fuel consumed during the simmer phase (moist) | AM28: g | AP28: =AL7-AP7 -> 0 | AQ28: fsm
U29: Net change in char during test | V29: g | W29: =AA17-$N$19 -> 0 | X29: Δcc | AA29: =IF(AA28=0,0,AI17-$N$19) -> 0 | AB29: Δch | AE29: Net change in char during test phase | AM29: g | AP29: =(AP17-$N$19)-W29 -> 0 | AQ29: Δcs
U30: Equivalent dry fuel consumed | V30: g | W30: =(W28*($E$20*(1-$E$18)-$E$18*(4.186*($N$20-$E$15)+2257))-W29*$E23)/$E$20 -> #DIV/0! | X30: fcd | AA30: =IF(AA28=0,0,(AA28*($E$20*(1-$E$18)-$E$18*(4.186*($N$20-$E$15)+2257))-AA29*$E23)/$E$20) -> 0 | AB30: fhd | AE30: Equivalent dry fuel consumed | AM30: g | AP30: =(AP28*($E$20*(1-$E$18)-$E$18*(4.186*($N$20-$E$15)+2257))-AP29*$E23)/$E$20 -> #DIV/0! | AQ30: fsd
U31: Water vaporized from all pots | V31: g | W31: =SUM(W12:W15)-SUM(AA12:AA15) -> 0 | X31: wcv | AA31: =SUM(AE12:AE15)-SUM(AI12:AI15) -> 0 | AB31: whv | AE31: Water vaporized | AM31: g | AP31: =(AL12-AP12)+(AL13-AP13)+(AL14-AP14)+(AL15-AP15) -> 0 | AQ31: wsv
U32: Effective mass of water boiled | V32: g | W32: =((AA12-$N15)*(AA8-W8)/($N$20-W8)+(AA13-$N16)*(AA9-W9)/($N$20-W9)+(AA14-$N17)*(AA10-W10)/($N$20-W10)+(AA15-$N18)*(AA11-W11)/($N$20-W11)) -> #DIV/0! | X32: wcr | AA32: =((AI12-$N15)*(AI8-AE8)/($N$20-AE8)+(AI13-$N16)*(AI9-AE9)/($N$20-AE9)+(AI14-$N17)*(AI10-AE10)/($N$20-AE10)+(AI15-$N18)*(AI11-AE11)/($N$20-AE11)) -> #DIV/0! | AB32: whr | AE32: Water remaining at end - All Pots | AM32: g | AP32: =(AP12-$N$15+((AP9-25)/(N20-25))*(AP13-N16)+((AP10-25)/(N20-25))*(AP14-N17)+((AP11-25)/(N20-25))*(AP15-N18)) -> 0 | AQ32: wsr
U33: Time to boil Pot # 1 | V33: min | W33: =(AA6-W6)*1440 -> 0 | X33: Δtc | AA33: =(AI6-AE6)*1440 -> 0 | AB33: Δth | AE33: Time of simmer (should be ~45 minutes) | AM33: min | AP33: =(AP6-AL6)*1440 -> 0 | AQ33: Δts
U34: Temp-corr time to boil Pot # 1 | V34: min | W34: =W33*75/(N20-W8) -> #DIV/0! | X34: ΔtTc | AA34: =AA33*75/(N20-AE8) -> #DIV/0! | AB34: ΔtTh | AE34: Thermal efficiency | AM34: % | AP34: =(4.186*((AL12-$N15+AP32)/2)*(AP8-AL8)+2260*AP31)/(AP30*$E$20) -> #DIV/0! | AQ34: hs
U35: Thermal efficiency | V35: % | W35: =(4.186*SUM((W12-$N15)*(AA8-W8),(W13-$N16)*(AA9-W9),(W14-$N17)*(AA10-W10),(W15-$N18)*(AA11-W11))+2260*W31)/(W30*$E20) -> #DIV/0! | X35: hc | AA35: =(4.186*SUM((AE12-$N15)*(AI8-AE8),(AE13-$N16)*(AI9-AE9),(AE14-$N17)*(AI10-AE10),(AE15-$N18)*(AI11-AE11))+2260*AA31)/(AA30*$E20) -> #DIV/0! | AB35: hh | AE35: Burning rate | AM35: g/min | AP35: =AP30/AP33 -> #DIV/0! | AQ35: rsb
B36: BASIC TEST DATA | U36: Burning rate | V36: g/min | W36: =W30/W33 -> #DIV/0! | X36: rcb | AA36: =AA30/AA33 -> #DIV/0! | AB36: rhb | AE36: Specific fuel consumption | AM36: g/liter remaining | AP36: =AP30/AP32*1000 -> #DIV/0! | AQ36: SCs
U37: Specific fuel consumption | V37: g/liter boiled | W37: =1000*W30/((W32)) -> #DIV/0! | X37: SCc | AA37: =1000*AA30/AA32 -> #DIV/0! | AB37: SCh | AE37: Firepower | AM37: watts | AP37: =AP30*$E$20/(AP33*60) -> #DIV/0! | AQ37: FPs
B38: ="TEST #1 "&D7 -> TEST #1 | U38: Temp-corr sp consumption | V38: g/liter | W38: =W37*75/($N$20-W8) -> #DIV/0! | X38: SCTc | AA38: =AA37*75/($N$20-AE8) -> #DIV/0! | AB38: SCTh | AE38: Turn down ratio | AM38: -- | AP38: =W40/AP37 -> #DIV/0! | AQ38: TDR
B39: Notes on the High Power - Cold Start Test. Add description only if it differs from "General Information" sheet | U39: Temp-corr sp energy consumpt. | V39: kJ/liter | W39: =(W38/1000)*E20 -> #DIV/0! | X39: SETC | AA39: =(AA38/1000)*E20 -> #DIV/0! | AB39: SETH | AE39: Specific Energy Consumption | AM39: kJ/liter | AP39: =(AP36/1000)*E20 -> #DIV/0! | AQ39: SES
U40: Firepower | V40: watts | W40: =W30*$E$20/(W33*60) -> #DIV/0! | X40: FPc | AA40: =AA30*$E$20/(AA33*60) -> #DIV/0! | AB40: FPh | AE40: Fuel Benchmark to Complete 5L WBT | AM40: g | AP40: =IF(ISERROR(AA38),5*(W38+AP36),5*(AVERAGE(W38,AA38)+AP36)) -> #DIV/0! | AQ40: BF
AE41: Energy Benchmark to Complete 5L WBT | AM41: kJ | AP41: =(AP40/1000)*E20 -> #DIV/0! | AQ41: BE
...

Sheet Test-2
A2: ="WATER BOILING TEST - VERSION "&version&" - TEST #2" -> WATER BOILING TEST - VERSION 4.2.3 - TEST #2 | U2: ="TEST #2 "&D7 -> TEST #2 | W2: COLD START HIGH POWER | AE2: HOT START HIGH POWER (OPTIONAL) | AL2: SIMMER TEST
B3: DATA AND CALCULATION FORM (for one to four pots)* | W3: Start | AA3: Finish: when | AE3: Start | AI3: Finish: when | AL3: Start | AP3: Finish: 45 min
B4: Shaded cells and arrows require user input; unshaded cells automatically display outputs | AA4: Pot #1 boils | AI4: Pot #1 boils
B5: Qualitative data | U5: Measurements | V5: Units | W5: data | X5: label | AA5: data | AB5: label | AE5: data | AF5: label | AI5: data | AJ5: label | AL5: data | AM5: label | AP5: data | AQ5: label
B6: Name(s) of Tester(s) | M6: gray: efficiency | U6: Time (in 24 hour form) | V6: hr:min | X6: tci | AB6: tcf | AF6: thi | AJ6: thf | AM6: tsi | AQ6: tsf
B7: Test Number | M7: blue: emissions | U7: Weight of fuel | V7: g | X7: fci | AB7: fcf | AF7: fhi | AJ7: fhf | AM7: fsi | AQ7: fsf
B8: Date | M8: pink: error, missing input | U8: Water temperature, Pot # 1 | V8: ºC | X8: T1ci | AB8: T1cf | AF8: T1hi | AJ8: T1hf | AM8: T1si | AQ8: T1sf
B9: Location | D9: ='General Information'!C7 -> 0 | U9: Water temperature, Pot # 2 | V9: ºC | X9: T2ci | AB9: T2cf | AF9: T2hi | AJ9: T2hf | AM9: T2si | AQ9: T2sf
B10: Stove type/model | D10: ='General Information'!C10 -> 0 | U10: Water temperature, Pot # 3 | V10: ºC | X10: T3ci | AB10: T3cf | AF10: T3hi | AJ10: T3hf | AM10: T3si | AQ10: T3sf
B11: Type of fuel | D11: ='General Information'!J3 -> 0 | U11: Water temperature, Pot # 4 | V11: ºC | X11: T4ci | AB11: T4cf | AF11: T4hi | AJ11: T4hf | AM11: T4si | AQ11: T4sf
U12: Weight of Pot # 1 with water | V12: g | X12: P1ci | AB12: P1cf | AF12: P1hi | AJ12: P1hf | AM12: P1si | AQ12: P1sf
B13: Initial Test Conditions | U13: Weight of Pot # 2 with water | V13: g | X13: P2ci | AB13: P2cf | AF13: P2hi | AJ13: P2hf | AM13: P2si | AQ13: P2sf
B14: Data | E14: value | G14: units | I14: label | K14: Data | N14: value | P14: units | R14: label | U14: Weight of Pot # 3 with water | V14: g | X14: P3ci | AB14: P3cf | AF14: P3hi | AJ14: P3hf | AM14: P3si | AQ14: P3sf
B15: Air temperature | G15: ºC | K15: Dry weight of Pot # 1 (grams) | P15: g | R15: P1 | U15: Weight of Pot # 4 with water | V15: g | X15: P4ci | AB15: P4cf | AF15: P4hi | AJ15: P4hf | AM15: P4si | AQ15: P4sf
B16: Wind conditions | E16: 1 | K16: Dry weight of Pot # 2 (grams) | P16: g | R16: P2 | U16: Fire-starting materials (if any) | V16: --
B17: Fuel dimensions | K17: Dry weight of Pot # 3 (grams) | P17: g | R17: P3 | U17: Weight of charcoal+container | V17: g | AB17: cc | AI17: =AA17 -> 0 | AJ17: ch | AQ17: cs
B18: Fuel moisture content (wet basis) | G18: % | I18: MC | K18: Dry weight of Pot # 4 (grams) | P18: g | R18: P4 | U18: Average CO2 | V18: ppm | AB18: CO2c | AJ18: CO2h | AQ18: CO2s
B19: Gross calorific value (dry fuel) | E19: ='General Information'!L21 -> 0 | G19: kJ/kg | I19: HHV | K19: Weight of container for char (grams) | P19: g | R19: k | U19: Average CO | V19: ppm | Z19: 10 | AB19: COc | AJ19: COh | AQ19: COs
B20: Net calorific value (dry fuel) | E20: ='General Information'!L22 -> 0 | G20: kJ/kg | I20: LHV | K20: Local boiling point | N20: ='General Information'!C20 -> 0 | P20: ºC | R20: Tb | U20: Average PM | V20: ug/m3 | AB20: PMc | AJ20: PMh | AQ20: PMs
B21: Effective calorific value | K21: Background concentrations: CO2 | P21: ppm | R21: CO2,b | U21: Average Duct Temperature | V21: ºC | AB21: Tcd | AJ21: Thd | AQ21: Tsd
B22: (accounting for fuel moisture) | E22: =E20*(1-E18)-(E18*((N20-E15)*4.2+2260)) -> 0 | G22: kJ/kg | I22: EHV | M22: CO | P22: ppm | R22: CO,b | U22: Total CO2 (if available) | V22: g | AB22: mCO2,c | AJ22: mCO2,h | AQ22: mCO2,s
B23: Char calorific value | E23: ='General Information'!L11 -> 0 | G23: kJ/kg | M23: PM | P23: ug/m3 | R23: PM,b | U23: Total CO (if available) | V23: g | Z23: 10 | AB23: mCO,c | AJ23: mCO,h | AQ23: mCO,s
U24: Total PM (if available) | V24: g | AB24: mPM,c | AJ24: mPM,h | AQ24: mPM,s
B25: Notes about this test:
W26: COLD START | AA26: HOT START | AE26: SIMMER TEST (CALCULATIONS DIFFER FROM HIGH POWER TEST)
U27: Calculations/Results | V27: Units | W27: data | X27: label | AA27: data | AB27: label | AE27: Calculations/Results | AM27: Units | AP27: data | AQ27: label
U28: Fuel consumed (moist) | V28: g | W28: =W7-AA7 -> 0 | X28: fcm | AA28: =AE7-AI7 -> 0 | AB28: fhm | AE28: Fuel consumed during the simmer phase (moist) | AM28: g | AP28: =AL7-AP7 -> 0 | AQ28: fsm
U29: Net change in char during test | V29: g | W29: =AA17-$N$19 -> 0 | X29: Δcc | AA29: =IF(AA28=0,0,AI17-$N$19) -> 0 | AB29: Δch | AE29: Net change in char during test phase | AM29: g | AP29: =(AP17-$N$19)-W29 -> 0 | AQ29: Δcs
U30: Equivalent dry fuel consumed | V30: g | W30: =(W28*($E$20*(1-$E$18)-$E$18*(4.186*($N$20-$E$15)+2257))-W29*$E23)/$E$20 -> #DIV/0! | X30: fcd | AA30: =IF(AA28=0,0,(AA28*($E$20*(1-$E$18)-$E$18*(4.186*($N$20-$E$15)+2257))-AA29*$E23)/$E$20) -> 0 | AB30: fhd | AE30: Equivalent dry fuel consumed | AM30: g | AP30: =(AP28*($E$20*(1-$E$18)-$E$18*(4.186*($N$20-$E$15)+2257))-AP29*$E23)/$E$20 -> #DIV/0! | AQ30: fsd
U31: Water vaporized from all pots | V31: g | W31: =SUM(W12:W15)-SUM(AA12:AA15) -> 0 | X31: wcv | AA31: =SUM(AE12:AE15)-SUM(AI12:AI15) -> 0 | AB31: whv | AE31: Water vaporized | AM31: g | AP31: =(AL12-AP12)+(AL13-AP13)+(AL14-AP14)+(AL15-AP15) -> 0 | AQ31: wsv
U32: Effective mass of water boiled | V32: g | W32: =((AA12-$N15)*(AA8-W8)/($N$20-W8)+(AA13-$N16)*(AA9-W9)/($N$20-W9)+(AA14-$N17)*(AA10-W10)/($N$20-W10)+(AA15-$N18)*(AA11-W11)/($N$20-W11)) -> #DIV/0! | X32: wcr | AA32: =((AI12-$N15)*(AI8-AE8)/($N$20-AE8)+(AI13-$N16)*(AI9-AE9)/($N$20-AE9)+(AI14-$N17)*(AI10-AE10)/($N$20-AE10)+(AI15-$N18)*(AI11-AE11)/($N$20-AE11)) -> #DIV/0! | AB32: whr | AE32: Water remaining at end - All Pots | AM32: g | AP32: =(AP12-$N$15+((AP9-25)/(N20-25))*(AP13-N16)+((AP10-25)/(N20-25))*(AP14-N17)+((AP11-25)/(N20-25))*(AP15-N18)) -> 0 | AQ32: wsr
U33: Time to boil Pot # 1 | V33: min | W33: =(AA6-W6)*1440 -> 0 | X33: Δtc | AA33: =(AI6-AE6)*1440 -> 0 | AB33: Δth | AE33: Time of simmer (should be ~45 minutes) | AM33: min | AP33: =(AP6-AL6)*1440 -> 0 | AQ33: Δts
U34: Temp-corr time to boil Pot # 1 | V34: min | W34: =W33*75/(N20-W8) -> #DIV/0! | X34: ΔtTc | AA34: =AA33*75/(N20-AE8) -> #DIV/0! | AB34: ΔtTh | AE34: Thermal efficiency | AM34: % | AP34: =(4.186*((AL12-$N15+AP32)/2)*(AP8-AL8)+2260*AP31)/(AP30*$E$20) -> #DIV/0! | AQ34: hs
U35: Thermal efficiency | V35: % | W35: =(4.186*SUM((W12-$N15)*(AA8-W8),(W13-$N16)*(AA9-W9),(W14-$N17)*(AA10-W10),(W15-$N18)*(AA11-W11))+2260*W31)/(W30*$E20) -> #DIV/0! | X35: hc | AA35: =(4.186*SUM((AE12-$N15)*(AI8-AE8),(AE13-$N16)*(AI9-AE9),(AE14-$N17)*(AI10-AE10),(AE15-$N18)*(AI11-AE11))+2260*AA31)/(AA30*$E20) -> #DIV/0! | AB35: hh | AE35: Burning rate | AM35: g/min | AP35: =AP30/AP33 -> #DIV/0! | AQ35: rsb
B36: BASIC TEST DATA | U36: Burning rate | V36: g/min | W36: =W30/W33 -> #DIV/0! | X36: rcb | AA36: =AA30/AA33 -> #DIV/0! | AB36: rhb | AE36: Specific fuel consumption | AM36: g/liter remaining | AP36: =AP30/AP32*1000 -> #DIV/0! | AQ36: SCs
U37: Specific fuel consumption | V37: g/liter boiled | W37: =1000*W30/((W32)) -> #DIV/0! | X37: SCc | AA37: =1000*AA30/AA32 -> #DIV/0! | AB37: SCh | AE37: Firepower | AM37: watts | AP37: =AP30*$E$20/(AP33*60) -> #DIV/0! | AQ37: FPs
B38: ="TEST #2 "&D7 -> TEST #2 | U38: Temp-corr sp consumption | V38: g/liter | W38: =W37*75/($N$20-W8) -> #DIV/0! | X38: SCTc | AA38: =AA37*75/($N$20-AE8) -> #DIV/0! | AB38: SCTh | AE38: Turn down ratio | AM38: -- | AP38: =W40/AP37 -> #DIV/0! | AQ38: TDR
B39: Notes on the High Power - Cold Start Test. Add description only if it differs from "General Information" sheet | U39: Temp-corr sp energy consumpt. | V39: kJ/liter | W39: =(W38/1000)*E20 -> #DIV/0! | X39: SETC | AA39: =(AA38/1000)*E20 -> #DIV/0! | AB39: SETH | AE39: Specific Energy Consumption | AM39: kJ/liter | AP39: =(AP36/1000)*E20 -> #DIV/0! | AQ39: SES
U40: Firepower | V40: watts | W40: =W30*$E$20/(W33*60) -> #DIV/0! | X40: FPc | AA40: =AA30*$E$20/(AA33*60) -> #DIV/0! | AB40: FPh | AE40: Fuel Benchmark to Complete 5L WBT | AM40: g | AP40: =IF(ISERROR(AA38),5*(W38+AP36),5*(AVERAGE(W38,AA38)+AP36)) -> #DIV/0! | AQ40: BF
AE41: Energy Benchmark to Complete 5L WBT | AM41: kJ | AP41: =(AP40/1000)*E20 -> #DIV/0! | AQ41: BE
...

Sheet Test-3
A2: ="WATER BOILING TEST - VERSION "&version&" - TEST #3" -> WATER BOILING TEST - VERSION 4.2.3 - TEST #3 | U2: ="TEST #3 "&D7 -> TEST #3 | W2: COLD START HIGH POWER | AE2: HOT START HIGH POWER (OPTIONAL) | AL2: SIMMER TEST
B3: DATA AND CALCULATION FORM (for one to four pots)* | W3: Start | AA3: Finish: when | AE3: Start | AI3: Finish: when | AL3: Start | AP3: Finish: 45 min
B4: Shaded cells and arrows require user input; unshaded cells automatically display outputs | AA4: Pot #1 boils | AI4: Pot #1 boils
B5: Qualitative data | U5: Measurements | V5: Units | W5: data | X5: label | AA5: data | AB5: label | AE5: data | AF5: label | AI5: data | AJ5: label | AL5: data | AM5: label | AP5: data | AQ5: label
B6: Name(s) of Tester(s) | M6: gray: efficiency | U6: Time (in 24 hour form) | V6: hr:min | X6: tci | AB6: tcf | AF6: thi | AJ6: thf | AM6: tsi | AQ6: tsf
B7: Test Number | M7: blue: emissions | U7: Weight of fuel | V7: g | X7: fci | AB7: fcf | AF7: fhi | AJ7: fhf | AM7: fsi | AQ7: fsf
B8: Date | M8: pink: error, missing input | U8: Water temperature, Pot # 1 | V8: ºC | X8: T1ci | AB8: T1cf | AF8: T1hi | AJ8: T1hf | AM8: T1si | AQ8: T1sf
B9: Location | D9: ='General Information'!C7 -> 0 | U9: Water temperature, Pot # 2 | V9: ºC | X9: T2ci | AB9: T2cf | AF9: T2hi | AJ9: T2hf | AM9: T2si | AQ9: T2sf
B10: Stove type/model | D10: ='General Information'!C10 -> 0 | U10: Water temperature, Pot # 3 | V10: ºC | X10: T3ci | AB10: T3cf | AF10: T3hi | AJ10: T3hf | AM10: T3si | AQ10: T3sf
B11: Type of fuel | D11: ='General Information'!J3 -> 0 | U11: Water temperature, Pot # 4 | V11: ºC | X11: T4ci | AB11: T4cf | AF11: T4hi | AJ11: T4hf | AM11: T4si | AQ11: T4sf
U12: Weight of Pot # 1 with water | V12: g | X12: P1ci | AB12: P1cf | AF12: P1hi | AJ12: P1hf | AM12: P1si | AQ12: P1sf
B13: Initial Test Conditions | U13: Weight of Pot # 2 with water | V13: g | X13: P2ci | AB13: P2cf | AF13: P2hi | AJ13: P2hf | AM13: P2si | AQ13: P2sf
B14: Data | E14: value | G14: units | I14: label | K14: Data | N14: value | P14: units | R14: label | U14: Weight of Pot # 3 with water | V14: g | X14: P3ci | AB14: P3cf | AF14: P3hi | AJ14: P3hf | AM14: P3si | AQ14: P3sf
B15: Air temperature | G15: ºC | K15: Dry weight of Pot # 1 (grams) | P15: g | R15: P1 | U15: Weight of Pot # 4 with water | V15: g | X15: P4ci | AB15: P4cf | AF15: P4hi | AJ15: P4hf | AM15: P4si | AQ15: P4sf
B16: Wind conditions | E16: 1 | K16: Dry weight of Pot # 2 (grams) | P16: g | R16: P2 | U16: Fire-starting materials (if any) | V16: --
B17: Fuel dimensions | K17: Dry weight of Pot # 3 (grams) | P17: g | R17: P3 | U17: Weight of charcoal+container | V17: g | AB17: cc | AI17: =AA17 -> 0 | AJ17: ch | AQ17: cs
B18: Fuel moisture content (wet basis) | G18: % | I18: MC | K18: Dry weight of Pot # 4 (grams) | P18: g | R18: P4 | U18: Average CO2 | V18: ppm | AB18: CO2c | AJ18: CO2h | AQ18: CO2s
B19: Gross calorific value (dry fuel) | E19: ='General Information'!L21 -> 0 | G19: kJ/kg | I19: HHV | K19: Weight of container for char (grams) | P19: g | R19: k | U19: Average CO | V19: ppm | Z19: 10 | AB19: COc | AJ19: COh | AQ19: COs
B20: Net calorific value (dry fuel) | E20: ='General Information'!L22 -> 0 | G20: kJ/kg | I20: LHV | K20: Local boiling point | N20: ='General Information'!C20 -> 0 | P20: ºC | R20: Tb | U20: Average PM | V20: ug/m3 | AB20: PMc | AJ20: PMh | AQ20: PMs
B21: Effective calorific value | K21: Background concentrations: CO2 | P21: ppm | R21: CO2,b | U21: Average Duct Temperature | V21: ºC | AB21: Tcd | AJ21: Thd | AQ21: Tsd
B22: (accounting for fuel moisture) | E22: =E20*(1-E18)-(E18*((N20-E15)*4.2+2260)) -> 0 | G22: kJ/kg | I22: EHV | M22: CO | P22: ppm | R22: CO,b | U22: Total CO2 (if available) | V22: g | AB22: mCO2,c | AJ22: mCO2,h | AQ22: mCO2,s
B23: Char calorific value | E23: ='General Information'!L11 -> 0 | G23: kJ/kg | M23: PM | P23: ug/m3 | R23: PM,b | U23: Total CO (if available) | V23: g | Z23: 10 | AB23: mCO,c | AJ23: mCO,h | AQ23: mCO,s
U24: Total PM (if available) | V24: g | AB24: mPM,c | AJ24: mPM,h | AQ24: mPM,s
B25: Notes about this test:
W26: COLD START | AA26: HOT START | AE26: SIMMER TEST (CALCULATIONS DIFFER FROM HIGH POWER TEST)
U27: Calculations/Results | V27: Units | W27: data | X27: label | AA27: data | AB27: label | AE27: Calculations/Results | AM27: Units | AP27: data | AQ27: label
U28: Fuel consumed (moist) | V28: g | W28: =W7-AA7 -> 0 | X28: fcm | AA28: =AE7-AI7 -> 0 | AB28: fhm | AE28: Fuel consumed during the simmer phase (moist) | AM28: g | AP28: =AL7-AP7 -> 0 | AQ28: fsm
U29: Net change in char during test | V29: g | W29: =AA17-$N$19 -> 0 | X29: Δcc | AA29: =IF(AA28=0,0,AI17-$N$19) -> 0 | AB29: Δch | AE29: Net change in char during test phase | AM29: g | AP29: =(AP17-$N$19)-W29 -> 0 | AQ29: Δcs
U30: Equivalent dry fuel consumed | V30: g | W30: =(W28*($E$20*(1-$E$18)-$E$18*(4.186*($N$20-$E$15)+2257))-W29*$E23)/$E$20 -> #DIV/0! | X30: fcd | AA30: =IF(AA28=0,0,(AA28*($E$20*(1-$E$18)-$E$18*(4.186*($N$20-$E$15)+2257))-AA29*$E23)/$E$20) -> 0 | AB30: fhd | AE30: Equivalent dry fuel consumed | AM30: g | AP30: =(AP28*($E$20*(1-$E$18)-$E$18*(4.186*($N$20-$E$15)+2257))-AP29*$E23)/$E$20 -> #DIV/0! | AQ30: fsd
U31: Water vaporized from all pots | V31: g | W31: =SUM(W12:W15)-SUM(AA12:AA15) -> 0 | X31: wcv | AA31: =SUM(AE12:AE15)-SUM(AI12:AI15) -> 0 | AB31: whv | AE31: Water vaporized | AM31: g | AP31: =(AL12-AP12)+(AL13-AP13)+(AL14-AP14)+(AL15-AP15) -> 0 | AQ31: wsv
U32: Effective mass of water boiled | V32: g | W32: =((AA12-$N15)*(AA8-W8)/($N$20-W8)+(AA13-$N16)*(AA9-W9)/($N$20-W9)+(AA14-$N17)*(AA10-W10)/($N$20-W10)+(AA15-$N18)*(AA11-W11)/($N$20-W11)) -> #DIV/0! | X32: wcr | AA32: =((AI12-$N15)*(AI8-AE8)/($N$20-AE8)+(AI13-$N16)*(AI9-AE9)/($N$20-AE9)+(AI14-$N17)*(AI10-AE10)/($N$20-AE10)+(AI15-$N18)*(AI11-AE11)/($N$20-AE11)) -> #DIV/0! | AB32: whr | AE32: Water remaining at end - All Pots | AM32: g | AP32: =(AP12-$N$15+((AP9-25)/(N20-25))*(AP13-N16)+((AP10-25)/(N20-25))*(AP14-N17)+((AP11-25)/(N20-25))*(AP15-N18)) -> 0 | AQ32: wsr
U33: Time to boil Pot # 1 | V33: min | W33: =(AA6-W6)*1440 -> 0 | X33: Δtc | AA33: =(AI6-AE6)*1440 -> 0 | AB33: Δth | AE33: Time of simmer (should be ~45 minutes) | AM33: min | AP33: =(AP6-AL6)*1440 -> 0 | AQ33: Δts
U34: Temp-corr time to boil Pot # 1 | V34: min | W34: =W33*75/(N20-W8) -> #DIV/0! | X34: ΔtTc | AA34: =AA33*75/(N20-AE8) -> #DIV/0! | AB34: ΔtTh | AE34: Thermal efficiency | AM34: % | AP34: =(4.186*((AL12-$N15+AP32)/2)*(AP8-AL8)+2260*AP31)/(AP30*$E$20) -> #DIV/0! | AQ34: hs
U35: Thermal efficiency | V35: % | W35: =(4.186*SUM((W12-$N15)*(AA8-W8),(W13-$N16)*(AA9-W9),(W14-$N17)*(AA10-W10),(W15-$N18)*(AA11-W11))+2260*W31)/(W30*$E20) -> #DIV/0! | X35: hc | AA35: =(4.186*SUM((AE12-$N15)*(AI8-AE8),(AE13-$N16)*(AI9-AE9),(AE14-$N17)*(AI10-AE10),(AE15-$N18)*(AI11-AE11))+2260*AA31)/(AA30*$E20) -> #DIV/0! | AB35: hh | AE35: Burning rate | AM35: g/min | AP35: =AP30/AP33 -> #DIV/0! | AQ35: rsb
B36: BASIC TEST DATA | U36: Burning rate | V36: g/min | W36: =W30/W33 -> #DIV/0! | X36: rcb | AA36: =AA30/AA33 -> #DIV/0! | AB36: rhb | AE36: Specific fuel consumption | AM36: g/liter remaining | AP36: =AP30/AP32*1000 -> #DIV/0! | AQ36: SCs
U37: Specific fuel consumption | V37: g/liter boiled | W37: =1000*W30/W32 -> #DIV/0! | X37: SCc | AA37: =1000*AA30/AA32 -> #DIV/0! | AB37: SCh | AE37: Firepower | AM37: watts | AP37: =AP30*$E$20/(AP33*60) -> #DIV/0! | AQ37: FPs
B38: ="TEST #3 "&D7 -> TEST #3 | U38: Temp-corr sp consumption | V38: g/liter | W38: =W37*75/($N$20-W8) -> #DIV/0! | X38: SCTc | AA38: =AA37*75/($N$20-AE8) -> #DIV/0! | AB38: SCTh | AE38: Turn down ratio | AM38: -- | AP38: =W40/AP37 -> #DIV/0! | AQ38: TDR
B39: Notes on the High Power - Cold Start Test. Add description only if it differs from "General Information" sheet | U39: Temp-corr sp energy consumpt. | V39: kJ/liter | W39: =(W38/1000)*E20 -> #DIV/0! | X39: SETC | AA39: =(AA38/1000)*E20 -> #DIV/0! | AB39: SETH | AE39: Specific Energy Consumption | AM39: kJ/liter | AP39: =(AP36/1000)*E20 -> #DIV/0! | AQ39: SES
U40: Firepower | V40: watts | W40: =W30*$E$20/(W33*60) -> #DIV/0! | X40: FPc | AA40: =AA30*$E$20/(AA33*60) -> #DIV/0! | AB40: FPh | AE40: Fuel Benchmark to Complete 5L WBT | AM40: g | AP40: =IF(ISERROR(AA38),5*(W38+AP36),5*(AVERAGE(W38,AA38)+AP36)) -> #DIV/0! | AQ40: BF
AE41: Energy Benchmark to Complete 5L WBT | AM41: kJ | AP41: =(AP40/1000)*E20 -> #DIV/0! | AQ41: BE
...

Sheet Test-4
A2: ="WATER BOILING TEST - VERSION "&version&" - TEST #4" -> WATER BOILING TEST - VERSION 4.2.3 - TEST #4 | U2: ="TEST #4 "&D7 -> TEST #4 | W2: COLD START HIGH POWER | AE2: HOT START HIGH POWER (OPTIONAL) | AL2: SIMMER TEST
B3: DATA AND CALCULATION FORM (for one to four pots)* | W3: Start | AA3: Finish: when | AE3: Start | AI3: Finish: when | AL3: Start | AP3: Finish: 45 min
B4: Shaded cells and arrows require user input; unshaded cells automatically display outputs | AA4: Pot #1 boils | AI4: Pot #1 boils
B5: Qualitative data | U5: Measurements | V5: Units | W5: data | X5: label | AA5: data | AB5: label | AE5: data | AF5: label | AI5: data | AJ5: label | AL5: data | AM5: label | AP5: data | AQ5: label
B6: Name(s) of Tester(s) | M6: gray: efficiency | U6: Time (in 24 hour form) | V6: hr:min | X6: tci | AB6: tcf | AF6: thi | AJ6: thf | AM6: tsi | AQ6: tsf
B7: Test Number | M7: blue: emissions | U7: Weight of fuel | V7: g | X7: fci | AB7: fcf | AF7: fhi | AJ7: fhf | AM7: fsi | AQ7: fsf
B8: Date | M8: pink: error, missing input | U8: Water temperature, Pot # 1 | V8: ºC | X8: T1ci | AB8: T1cf | AF8: T1hi | AJ8: T1hf | AM8: T1si | AQ8: T1sf
B9: Location | D9: ='General Information'!C7 -> 0 | U9: Water temperature, Pot # 2 | V9: ºC | X9: T2ci | AB9: T2cf | AF9: T2hi | AJ9: T2hf | AM9: T2si | AQ9: T2sf
B10: Stove type/model | D10: ='General Information'!C10 -> 0 | U10: Water temperature, Pot # 3 | V10: ºC | X10: T3ci | AB10: T3cf | AF10: T3hi | AJ10: T3hf | AM10: T3si | AQ10: T3sf
B11: Type of fuel | D11: ='General Information'!J3 -> 0 | U11: Water temperature, Pot # 4 | V11: ºC | X11: T4ci | AB11: T4cf | AF11: T4hi | AJ11: T4hf | AM11: T4si | AQ11: T4sf
U12: Weight of Pot # 1 with water | V12: g | X12: P1ci | AB12: P1cf | AF12: P1hi | AJ12: P1hf | AM12: P1si | AQ12: P1sf
B13: Initial Test Conditions | U13: Weight of Pot # 2 with water | V13: g | X13: P2ci | AB13: P2cf | AF13: P2hi | AJ13: P2hf | AM13: P2si | AQ13: P2sf
B14: Data | E14: value | G14: units | I14: label | K14: Data | N14: value | P14: units | R14: label | U14: Weight of Pot # 3 with water | V14: g | X14: P3ci | AB14: P3cf | AF14: P3hi | AJ14: P3hf | AM14: P3si | AQ14: P3sf
B15: Air temperature | G15: ºC | K15: Dry weight of Pot # 1 (grams) | P15: g | R15: P1 | U15: Weight of Pot # 4 with water | V15: g | X15: P4ci | AB15: P4cf | AF15: P4hi | AJ15: P4hf | AM15: P4si | AQ15: P4sf
B16: Wind conditions | E16: 1 | K16: Dry weight of Pot # 2 (grams) | P16: g | R16: P2 | U16: Fire-starting materials (if any) | V16: --
B17: Fuel dimensions | K17: Dry weight of Pot # 3 (grams) | P17: g | R17: P3 | U17: Weight of charcoal+container | V17: g | AB17: cc | AI17: =AA17 -> 0 | AJ17: ch | AQ17: cs
B18: Fuel moisture content (wet basis) | G18: % | I18: MC | K18: Dry weight of Pot # 4 (grams) | P18: g | R18: P4 | U18: Average CO2 | V18: ppm | AB18: CO2c | AJ18: CO2h | AQ18: CO2s
B19: Gross calorific value (dry fuel) | E19: ='General Information'!L21 -> 0 | G19: kJ/kg | I19: HHV | K19: Weight of container for char (grams) | P19: g | R19: k | U19: Average CO | V19: ppm | Z19: 10 | AB19: COc | AJ19: COh | AQ19: COs
B20: Net calorific value (dry fuel) | E20: ='General Information'!L22 -> 0 | G20: kJ/kg | I20: LHV | K20: Local boiling point | N20: ='General Information'!C20 -> 0 | P20: ºC | R20: Tb | U20: Average PM | V20: ug/m3 | AB20: PMc | AJ20: PMh | AQ20: PMs
B21: Effective calorific value | K21: Background concentrations: CO2 | P21: ppm | R21: CO2,b | U21: Average Duct Temperature | V21: ºC | AB21: Tcd | AJ21: Thd | AQ21: Tsd
B22: (accounting for fuel moisture) | E22: =E20*(1-E18)-(E18*((N20-E15)*4.2+2260)) -> 0 | G22: kJ/kg | I22: EHV | M22: CO | P22: ppm | R22: CO,b | U22: Total CO2 (if available) | V22: g | AB22: mCO2,c | AJ22: mCO2,h | AQ22: mCO2,s
B23: Char calorific value | E23: ='General Information'!L11 -> 0 | G23: kJ/kg | M23: PM | P23: ug/m3 | R23: PM,b | U23: Total CO (if available) | V23: g | Z23: 10 | AB23: mCO,c | AJ23: mCO,h | AQ23: mCO,s
U24: Total PM (if available) | V24: g | AB24: mPM,c | AJ24: mPM,h | AQ24: mPM,s
B25: Notes about this test:
W26: COLD START | AA26: HOT START | AE26: SIMMER TEST (CALCULATIONS DIFFER FROM HIGH POWER TEST)
U27: Calculations/Results | V27: Units | W27: data | X27: label | AA27: data | AB27: label | AE27: Calculations/Results | AM27: Units | AP27: data | AQ27: label
U28: Fuel consumed (moist) | V28: g | W28: =W7-AA7 -> 0 | X28: fcm | AA28: =AE7-AI7 -> 0 | AB28: fhm | AE28: Fuel consumed during the simmer phase (moist) | AM28: g | AP28: =AL7-AP7 -> 0 | AQ28: fsm
U29: Net change in char during test | V29: g | W29: =AA17-$N$19 -> 0 | X29: Δcc | AA29: =IF(AA28=0,0,AI17-$N$19) -> 0 | AB29: Δch | AE29: Net change in char during test phase | AM29: g | AP29: =(AP17-$N$19)-W29 -> 0 | AQ29: Δcs
U30: Equivalent dry fuel consumed | V30: g | W30: =(W28*($E$20*(1-$E$18)-$E$18*(4.186*($N$20-$E$15)+2257))-W29*$E23)/$E$20 -> #DIV/0! | X30: fcd | AA30: =IF(AA28=0,0,(AA28*($E$20*(1-$E$18)-$E$18*(4.186*($N$20-$E$15)+2257))-AA29*$E23)/$E$20) -> 0 | AB30: fhd | AE30: Equivalent dry fuel consumed | AM30: g | AP30: =(AP28*($E$20*(1-$E$18)-$E$18*(4.186*($N$20-$E$15)+2257))-AP29*$E23)/$E$20 -> #DIV/0! | AQ30: fsd
U31: Water vaporized from all pots | V31: g | W31: =SUM(W12:W15)-SUM(AA12:AA15) -> 0 | X31: wcv | AA31: =SUM(AE12:AE15)-SUM(AI12:AI15) -> 0 | AB31: whv | AE31: Water vaporized | AM31: g | AP31: =(AL12-AP12)+(AL13-AP13)+(AL14-AP14)+(AL15-AP15) -> 0 | AQ31: wsv
U32: Effective mass of water boiled | V32: g | W32: =((AA12-$N15)*(AA8-W8)/($N$20-W8)+(AA13-$N16)*(AA9-W9)/($N$20-W9)+(AA14-$N17)*(AA10-W10)/($N$20-W10)+(AA15-$N18)*(AA11-W11)/($N$20-W11)) -> #DIV/0! | X32: wcr | AA32: =((AI12-$N15)*(AI8-AE8)/($N$20-AE8)+(AI13-$N16)*(AI9-AE9)/($N$20-AE9)+(AI14-$N17)*(AI10-AE10)/($N$20-AE10)+(AI15-$N18)*(AI11-AE11)/($N$20-AE11)) -> #DIV/0! | AB32: whr | AE32: Water remaining at end - All Pots | AM32: g | AP32: =(AP12-$N$15+((AP9-25)/(N20-25))*(AP13-N16)+((AP10-25)/(N20-25))*(AP14-N17)+((AP11-25)/(N20-25))*(AP15-N18)) -> 0 | AQ32: wsr
U33: Time to boil Pot # 1 | V33: min | W33: =(AA6-W6)*1440 -> 0 | X33: Δtc | AA33: =(AI6-AE6)*1440 -> 0 | AB33: Δth | AE33: Time of simmer (should be ~45 minutes) | AM33: min | AP33: =(AP6-AL6)*1440 -> 0 | AQ33: Δts
U34: Temp-corr time to boil Pot # 1 | V34: min | W34: =W33*75/(N20-W8) -> #DIV/0! | X34: ΔtTc | AA34: =AA33*75/(N20-AE8) -> #DIV/0! | AB34: ΔtTh | AE34: Thermal efficiency | AM34: % | AP34: =(4.186*((AL12-$N15+AP32)/2)*(AP8-AL8)+2260*AP31)/(AP30*$E$20) -> #DIV/0! | AQ34: hs
U35: Thermal efficiency | V35: % | W35: =(4.186*SUM((W12-$N15)*(AA8-W8),(W13-$N16)*(AA9-W9),(W14-$N17)*(AA10-W10),(W15-$N18)*(AA11-W11))+2260*W31)/(W30*$E20) -> #DIV/0! | X35: hc | AA35: =(4.186*SUM((AE12-$N15)*(AI8-AE8),(AE13-$N16)*(AI9-AE9),(AE14-$N17)*(AI10-AE10),(AE15-$N18)*(AI11-AE11))+2260*AA31)/(AA30*$E20) -> #DIV/0! | AB35: hh | AE35: Burning rate | AM35: g/min | AP35: =AP30/AP33 -> #DIV/0! | AQ35: rsb
B36: BASIC TEST DATA | U36: Burning rate | V36: g/min | W36: =W30/W33 -> #DIV/0! | X36: rcb | AA36: =AA30/AA33 -> #DIV/0! | AB36: rhb | AE36: Specific fuel consumption | AM36: g/liter remaining | AP36: =AP30/AP32*1000 -> #DIV/0! | AQ36: SCs
U37: Specific fuel consumption | V37: g/liter boiled | W37: =1000*W30/W32 -> #DIV/0! | X37: SCc | AA37: =1000*AA30/AA32 -> #DIV/0! | AB37: SCh | AE37: Firepower | AM37: watts | AP37: =AP30*$E$20/(AP33*60) -> #DIV/0! | AQ37: FPs
B38: ="TEST #4 "&D7 -> TEST #4 | U38: Temp-corr sp consumption | V38: g/liter | W38: =W37*75/($N$20-W8) -> #DIV/0! | X38: SCTc | AA38: =AA37*75/($N$20-AE8) -> #DIV/0! | AB38: SCTh | AE38: Turn down ratio | AM38: -- | AP38: =W40/AP37 -> #DIV/0! | AQ38: TDR
B39: Notes on the High Power - Cold Start Test. Add description only if it differs from "General Information" sheet | U39: Temp-corr sp energy consumpt. | V39: kJ/liter | W39: =(W38/1000)*E20 -> #DIV/0! | X39: SETC | AA39: =(AA38/1000)*E20 -> #DIV/0! | AB39: SETH | AE39: Specific Energy Consumption | AM39: kJ/liter | AP39: =(AP36/1000)*E20 -> #DIV/0! | AQ39: SES
U40: Firepower | V40: watts | W40: =W30*$E$20/(W33*60) -> #DIV/0! | X40: FPc | AA40: =AA30*$E$20/(AA33*60) -> #DIV/0! | AB40: FPh | AE40: Fuel Benchmark to Complete 5L WBT | AM40: g | AP40: =IF(ISERROR(AA38),5*(W38+AP36),5*(AVERAGE(W38,AA38)+AP36)) -> #DIV/0! | AQ40: BF
AE41: Energy Benchmark to Complete 5L WBT | AM41: kJ | AP41: =(AP40/1000)*E20 -> #DIV/0! | AQ41: BE
...

Sheet Test-5
A2: ="WATER BOILING TEST - VERSION "&version&" - TEST #5" -> WATER BOILING TEST - VERSION 4.2.3 - TEST #5 | U2: ="TEST #5 "&D7 -> TEST #5 | W2: COLD START HIGH POWER | AE2: HOT START HIGH POWER (OPTIONAL) | AL2: SIMMER TEST
B3: DATA AND CALCULATION FORM (for one to four pots)* | W3: Start | AA3: Finish: when | AE3: Start | AI3: Finish: when | AL3: Start | AP3: Finish: 45 min
B4: Shaded cells and arrows require user input; unshaded cells automatically display outputs | AA4: Pot #1 boils | AI4: Pot #1 boils
B5: Qualitative data | U5: Measurements | V5: Units | W5: data | X5: label | AA5: data | AB5: label | AE5: data | AF5: label | AI5: data | AJ5: label | AL5: data | AM5: label | AP5: data | AQ5: label
B6: Name(s) of Tester(s) | M6: gray: efficiency | U6: Time (in 24 hour form) | V6: hr:min | X6: tci | AB6: tcf | AF6: thi | AJ6: thf | AM6: tsi | AQ6: tsf
B7: Test Number | M7: blue: emissions | U7: Weight of fuel | V7: g | X7: fci | AB7: fcf | AF7: fhi | AJ7: fhf | AM7: fsi | AQ7: fsf
B8: Date | M8: pink: error, missing input | U8: Water temperature, Pot # 1 | V8: ºC | X8: T1ci | AB8: T1cf | AF8: T1hi | AJ8: T1hf | AM8: T1si | AQ8: T1sf
B9: Location | D9: ='General Information'!C7 -> 0 | U9: Water temperature, Pot # 2 | V9: ºC | X9: T2ci | AB9: T2cf | AF9: T2hi | AJ9: T2hf | AM9: T2si | AQ9: T2sf
B10: Stove type/model | D10: ='General Information'!C10 -> 0 | U10: Water temperature, Pot # 3 | V10: ºC | X10: T3ci | AB10: T3cf | AF10: T3hi | AJ10: T3hf | AM10: T3si | AQ10: T3sf
B11: Type of fuel | D11: ='General Information'!J3 -> 0 | U11: Water temperature, Pot # 4 | V11: ºC | X11: T4ci | AB11: T4cf | AF11: T4hi | AJ11: T4hf | AM11: T4si | AQ11: T4sf
U12: Weight of Pot # 1 with water | V12: g | X12: P1ci | AB12: P1cf | AF12: P1hi | AJ12: P1hf | AM12: P1si | AQ12: P1sf
B13: Initial Test Conditions | U13: Weight of Pot # 2 with water | V13: g | X13: P2ci | AB13: P2cf | AF13: P2hi | AJ13: P2hf | AM13: P2si | AQ13: P2sf
B14: Data | E14: value | G14: units | I14: label | K14: Data | N14: value | P14: units | R14: label | U14: Weight of Pot # 3 with water | V14: g | X14: P3ci | AB14: P3cf | AF14: P3hi | AJ14: P3hf | AM14: P3si | AQ14: P3sf
B15: Air temperature | G15: ºC | K15: Dry weight of Pot # 1 (grams) | P15: g | R15: P1 | U15: Weight of Pot # 4 with water | V15: g | X15: P4ci | AB15: P4cf | AF15: P4hi | AJ15: P4hf | AM15: P4si | AQ15: P4sf
B16: Wind conditions | E16: 1 | K16: Dry weight of Pot # 2 (grams) | P16: g | R16: P2 | U16: Fire-starting materials (if any) | V16: --
B17: Fuel dimensions | K17: Dry weight of Pot # 3 (grams) | P17: g | R17: P3 | U17: Weight of charcoal+container | V17: g | AB17: cc | AI17: =AA17 -> 0 | AJ17: ch | AQ17: cs
B18: Fuel moisture content (wet basis) | G18: % | I18: MC | K18: Dry weight of Pot # 4 (grams) | P18: g | R18: P4 | U18: Average CO2 | V18: ppm | AB18: CO2c | AJ18: CO2h | AQ18: CO2s
B19: Gross calorific value (dry fuel) | E19: ='General Information'!L21 -> 0 | G19: kJ/kg | I19: HHV | K19: Weight of container for char (grams) | P19: g | R19: k | U19: Average CO | V19: ppm | Z19: 10 | AB19: COc | AJ19: COh | AQ19: COs
B20: Net calorific value (dry fuel) | E20: ='General Information'!L22 -> 0 | G20: kJ/kg | I20: LHV | K20: Local boiling point | N20: ='General Information'!C20 -> 0 | P20: ºC | R20: Tb | U20: Average PM | V20: ug/m3 | AB20: PMc | AJ20: PMh | AQ20: PMs
B21: Effective calorific value | K21: Background concentrations: CO2 | P21: ppm | R21: CO2,b | U21: Average Duct Temperature | V21: ºC | AB21: Tcd | AJ21: Thd | AQ21: Tsd
B22: (accounting for fuel moisture) | E22: =E20*(1-E18)-(E18*((N20-E15)*4.2+2260)) -> 0 | G22: kJ/kg | I22: EHV | M22: CO | P22: ppm | R22: CO,b | U22: Total CO2 (if available) | V22: g | AB22: mCO2,c | AJ22: mCO2,h | AQ22: mCO2,s
B23: Char calorific value | E23: ='General Information'!L11 -> 0 | G23: kJ/kg | M23: PM | P23: ug/m3 | R23: PM,b | U23: Total CO (if available) | V23: g | Z23: 10 | AB23: mCO,c | AJ23: mCO,h | AQ23: mCO,s
U24: Total PM (if available) | V24: g | AB24: mPM,c | AJ24: mPM,h | AQ24: mPM,s
B25: Notes about this test:
W26: COLD START | AA26: HOT START | AE26: SIMMER TEST (CALCULATIONS DIFFER FROM HIGH POWER TEST)
U27: Calculations/Results | V27: Units | W27: data | X27: label | AA27: data | AB27: label | AE27: Calculations/Results | AM27: Units | AP27: data | AQ27: label
U28: Fuel consumed (moist) | V28: g | W28: =W7-AA7 -> 0 | X28: fcm | AA28: =AE7-AI7 -> 0 | AB28: fhm | AE28: Fuel consumed during the simmer phase (moist) | AM28: g | AP28: =AL7-AP7 -> 0 | AQ28: fsm
U29: Net change in char during test | V29: g | W29: =AA17-$N$19 -> 0 | X29: Δcc | AA29: =IF(AA28=0,0,AI17-$N$19) -> 0 | AB29: Δch | AE29: Net change in char during test phase | AM29: g | AP29: =(AP17-$N$19)-W29 -> 0 | AQ29: Δcs
U30: Equivalent dry fuel consumed | V30: g | W30: =(W28*($E$20*(1-$E$18)-$E$18*(4.186*($N$20-$E$15)+2257))-W29*$E23)/$E$20 -> #DIV/0! | X30: fcd | AA30: =IF(AA28=0,0,(AA28*($E$20*(1-$E$18)-$E$18*(4.186*($N$20-$E$15)+2257))-AA29*$E23)/$E$20) -> 0 | AB30: fhd | AE30: Equivalent dry fuel consumed | AM30: g | AP30: =(AP28*($E$20*(1-$E$18)-$E$18*(4.186*($N$20-$E$15)+2257))-AP29*$E23)/$E$20 -> #DIV/0! | AQ30: fsd
U31: Water vaporized from all pots | V31: g | W31: =SUM(W12:W15)-SUM(AA12:AA15) -> 0 | X31: wcv | AA31: =SUM(AE12:AE15)-SUM(AI12:AI15) -> 0 | AB31: whv | AE31: Water vaporized | AM31: g | AP31: =(AL12-AP12)+(AL13-AP13)+(AL14-AP14)+(AL15-AP15) -> 0 | AQ31: wsv
U32: Effective mass of water boiled | V32: g | W32: =((AA12-$N15)*(AA8-W8)/($N$20-W8)+(AA13-$N16)*(AA9-W9)/($N$20-W9)+(AA14-$N17)*(AA10-W10)/($N$20-W10)+(AA15-$N18)*(AA11-W11)/($N$20-W11)) -> #DIV/0! | X32: wcr | AA32: =((AI12-$N15)*(AI8-AE8)/($N$20-AE8)+(AI13-$N16)*(AI9-AE9)/($N$20-AE9)+(AI14-$N17)*(AI10-AE10)/($N$20-AE10)+(AI15-$N18)*(AI11-AE11)/($N$20-AE11)) -> #DIV/0! | AB32: whr | AE32: Water remaining at end - All Pots | AM32: g | AP32: =(AP12-$N$15+((AP9-25)/(N20-25))*(AP13-N16)+((AP10-25)/(N20-25))*(AP14-N17)+((AP11-25)/(N20-25))*(AP15-N18)) -> 0 | AQ32: wsr
U33: Time to boil Pot # 1 | V33: min | W33: =(AA6-W6)*1440 -> 0 | X33: Δtc | AA33: =(AI6-AE6)*1440 -> 0 | AB33: Δth | AE33: Time of simmer (should be ~45 minutes) | AM33: min | AP33: =(AP6-AL6)*1440 -> 0 | AQ33: Δts
U34: Temp-corr time to boil Pot # 1 | V34: min | W34: =W33*75/(N20-W8) -> #DIV/0! | X34: ΔtTc | AA34: =AA33*75/(N20-AE8) -> #DIV/0! | AB34: ΔtTh | AE34: Thermal efficiency | AM34: % | AP34: =(4.186*((AL12-$N15+AP32)/2)*(AP8-AL8)+2260*AP31)/(AP30*$E$20) -> #DIV/0! | AQ34: hs
U35: Thermal efficiency | V35: % | W35: =(4.186*SUM((W12-$N15)*(AA8-W8),(W13-$N16)*(AA9-W9),(W14-$N17)*(AA10-W10),(W15-$N18)*(AA11-W11))+2260*W31)/(W30*$E20) -> #DIV/0! | X35: hc | AA35: =(4.186*SUM((AE12-$N15)*(AI8-AE8),(AE13-$N16)*(AI9-AE9),(AE14-$N17)*(AI10-AE10),(AE15-$N18)*(AI11-AE11))+2260*AA31)/(AA30*$E20) -> #DIV/0! | AB35: hh | AE35: Burning rate | AM35: g/min | AP35: =AP30/AP33 -> #DIV/0! | AQ35: rsb
B36: BASIC TEST DATA | U36: Burning rate | V36: g/min | W36: =W30/W33 -> #DIV/0! | X36: rcb | AA36: =AA30/AA33 -> #DIV/0! | AB36: rhb | AE36: Specific fuel consumption | AM36: g/liter remaining | AP36: =AP30/AP32*1000 -> #DIV/0! | AQ36: SCs
U37: Specific fuel consumption | V37: g/liter boiled | W37: =1000*W30/W32 -> #DIV/0! | X37: SCc | AA37: =1000*AA30/AA32 -> #DIV/0! | AB37: SCh | AE37: Firepower | AM37: watts | AP37: =AP30*$E$20/(AP33*60) -> #DIV/0! | AQ37: FPs
B38: ="TEST #5 "&D7 -> TEST #5 | U38: Temp-corr sp consumption | V38: g/liter | W38: =W37*75/($N$20-W8) -> #DIV/0! | X38: SCTc | AA38: =AA37*75/($N$20-AE8) -> #DIV/0! | AB38: SCTh | AE38: Turn down ratio | AM38: -- | AP38: =W40/AP37 -> #DIV/0! | AQ38: TDR
B39: Notes on the High Power - Cold Start Test. Add description only if it differs from "General Information" sheet | U39: Temp-corr sp energy consumpt. | V39: kJ/liter | W39: =(W38/1000)*E20 -> #DIV/0! | X39: SETC | AA39: =(AA38/1000)*E20 -> #DIV/0! | AB39: SETH | AE39: Specific Energy Consumption | AM39: kJ/liter | AP39: =(AP36/1000)*E20 -> #DIV/0! | AQ39: SES
U40: Firepower | V40: watts | W40: =W30*$E$20/(W33*60) -> #DIV/0! | X40: FPc | AA40: =AA30*$E$20/(AA33*60) -> #DIV/0! | AB40: FPh | AE40: Fuel Benchmark to Complete 5L WBT | AM40: g | AP40: =IF(ISERROR(AA38),5*(W38+AP36),5*(AVERAGE(W38,AA38)+AP36)) -> #DIV/0! | AQ40: BF
AE41: Energy Benchmark to Complete 5L WBT | AM41: kJ | AP41: =(AP40/1000)*E20 -> #DIV/0! | AQ41: BE
...

Sheet Test-6
A2: ="WATER BOILING TEST - VERSION "&version&" - TEST #6" -> WATER BOILING TEST - VERSION 4.2.3 - TEST #6 | U2: ="TEST #6 "&D7 -> TEST #6 | W2: COLD START HIGH POWER | AE2: HOT START HIGH POWER (OPTIONAL) | AL2: SIMMER TEST
B3: DATA AND CALCULATION FORM (for one to four pots)* | W3: Start | AA3: Finish: when | AE3: Start | AI3: Finish: when | AL3: Start | AP3: Finish: 45 min
B4: Shaded cells and arrows require user input; unshaded cells automatically display outputs | AA4: Pot #1 boils | AI4: Pot #1 boils
B5: Qualitative data | U5: Measurements | V5: Units | W5: data | X5: label | AA5: data | AB5: label | AE5: data | AF5: label | AI5: data | AJ5: label | AL5: data | AM5: label | AP5: data | AQ5: label
B6: Name(s) of Tester(s) | M6: gray: efficiency | U6: Time (in 24 hour form) | V6: hr:min | X6: tci | AB6: tcf | AF6: thi | AJ6: thf | AM6: tsi | AQ6: tsf
B7: Test Number | M7: blue: emissions | U7: Weight of fuel | V7: g | X7: fci | AB7: fcf | AF7: fhi | AJ7: fhf | AM7: fsi | AQ7: fsf
B8: Date | M8: pink: error, missing input | U8: Water temperature, Pot # 1 | V8: ºC | X8: T1ci | AB8: T1cf | AF8: T1hi | AJ8: T1hf | AM8: T1si | AQ8: T1sf
B9: Location | D9: ='General Information'!C7 -> 0 | U9: Water temperature, Pot # 2 | V9: ºC | X9: T2ci | AB9: T2cf | AF9: T2hi | AJ9: T2hf | AM9: T2si | AQ9: T2sf
B10: Stove type/model | D10: ='General Information'!C10 -> 0 | U10: Water temperature, Pot # 3 | V10: ºC | X10: T3ci | AB10: T3cf | AF10: T3hi | AJ10: T3hf | AM10: T3si | AQ10: T3sf
B11: Type of fuel | D11: ='General Information'!J3 -> 0 | U11: Water temperature, Pot # 4 | V11: ºC | X11: T4ci | AB11: T4cf | AF11: T4hi | AJ11: T4hf | AM11: T4si | AQ11: T4sf
U12: Weight of Pot # 1 with water | V12: g | X12: P1ci | AB12: P1cf | AF12: P1hi | AJ12: P1hf | AM12: P1si | AQ12: P1sf
B13: Initial Test Conditions | U13: Weight of Pot # 2 with water | V13: g | X13: P2ci | AB13: P2cf | AF13: P2hi | AJ13: P2hf | AM13: P2si | AQ13: P2sf
B14: Data | E14: value | G14: units | I14: label | K14: Data | N14: value | P14: units | R14: label | U14: Weight of Pot # 3 with water | V14: g | X14: P3ci | AB14: P3cf | AF14: P3hi | AJ14: P3hf | AM14: P3si | AQ14: P3sf
B15: Air temperature | G15: ºC | K15: Dry weight of Pot # 1 (grams) | P15: g | R15: P1 | U15: Weight of Pot # 4 with water | V15: g | X15: P4ci | AB15: P4cf | AF15: P4hi | AJ15: P4hf | AM15: P4si | AQ15: P4sf
B16: Wind conditions | E16: 1 | K16: Dry weight of Pot # 2 (grams) | P16: g | R16: P2 | U16: Fire-starting materials (if any) | V16: --
B17: Fuel dimensions | K17: Dry weight of Pot # 3 (grams) | P17: g | R17: P3 | U17: Weight of charcoal+container | V17: g | AB17: cc | AI17: =AA17 -> 0 | AJ17: ch | AQ17: cs
B18: Fuel moisture content (wet basis) | G18: % | I18: MC | K18: Dry weight of Pot # 4 (grams) | P18: g | R18: P4 | U18: Average CO2 | V18: ppm | AB18: CO2c | AJ18: CO2h | AQ18: CO2s
B19: Gross calorific value (dry fuel) | E19: ='General Information'!L21 -> 0 | G19: kJ/kg | I19: HHV | K19: Weight of container for char (grams) | P19: g | R19: k | U19: Average CO | V19: ppm | Z19: 10 | AB19: COc | AJ19: COh | AQ19: COs
B20: Net calorific value (dry fuel) | E20: ='General Information'!L22 -> 0 | G20: kJ/kg | I20: LHV | K20: Local boiling point | N20: ='General Information'!C20 -> 0 | P20: ºC | R20: Tb | U20: Average PM | V20: ug/m3 | AB20: PMc | AJ20: PMh | AQ20: PMs
B21: Effective calorific value | K21: Background concentrations: CO2 | P21: ppm | R21: CO2,b | U21: Average Duct Temperature | V21: ºC | AB21: Tcd | AJ21: Thd | AQ21: Tsd
B22: (accounting for fuel moisture) | E22: =E20*(1-E18)-(E18*((N20-E15)*4.2+2260)) -> 0 | G22: kJ/kg | I22: EHV | M22: CO | P22: ppm | R22: CO,b | U22: Total CO2 (if available) | V22: g | AB22: mCO2,c | AJ22: mCO2,h | AQ22: mCO2,s
B23: Char calorific value | E23: ='General Information'!L11 -> 0 | G23: kJ/kg | M23: PM | P23: ug/m3 | R23: PM,b | U23: Total CO (if available) | V23: g | Z23: 10 | AB23: mCO,c | AJ23: mCO,h | AQ23: mCO,s
U24: Total PM (if available) | V24: g | AB24: mPM,c | AJ24: mPM,h | AQ24: mPM,s
B25: Notes about this test:
W26: COLD START | AA26: HOT START | AE26: SIMMER TEST (CALCULATIONS DIFFER FROM HIGH POWER TEST)
U27: Calculations/Results | V27: Units | W27: data | X27: label | AA27: data | AB27: label | AE27: Calculations/Results | AM27: Units | AP27: data | AQ27: label
U28: Fuel consumed (moist) | V28: g | W28: =W7-AA7 -> 0 | X28: fcm | AA28: =AE7-AI7 -> 0 | AB28: fhm | AE28: Fuel consumed during the simmer phase (moist) | AM28: g | AP28: =AL7-AP7 -> 0 | AQ28: fsm
U29: Net change in char during test | V29: g | W29: =AA17-$N$19 -> 0 | X29: Δcc | AA29: =IF(AA28=0,0,AI17-$N$19) -> 0 | AB29: Δch | AE29: Net change in char during test phase | AM29: g | AP29: =(AP17-$N$19)-W29 -> 0 | AQ29: Δcs
U30: Equivalent dry fuel consumed | V30: g | W30: =(W28*($E$20*(1-$E$18)-$E$18*(4.186*($N$20-$E$15)+2257))-W29*$E23)/$E$20 -> #DIV/0! | X30: fcd | AA30: =IF(AA28=0,0,(AA28*($E$20*(1-$E$18)-$E$18*(4.186*($N$20-$E$15)+2257))-AA29*$E23)/$E$20) -> 0 | AB30: fhd | AE30: Equivalent dry fuel consumed | AM30: g | AP30: =(AP28*($E$20*(1-$E$18)-$E$18*(4.186*($N$20-$E$15)+2257))-AP29*$E23)/$E$20 -> #DIV/0! | AQ30: fsd
U31: Water vaporized from all pots | V31: g | W31: =SUM(W12:W15)-SUM(AA12:AA15) -> 0 | X31: wcv | AA31: =SUM(AE12:AE15)-SUM(AI12:AI15) -> 0 | AB31: whv | AE31: Water vaporized | AM31: g | AP31: =(AL12-AP12)+(AL13-AP13)+(AL14-AP14)+(AL15-AP15) -> 0 | AQ31: wsv
U32: Effective mass of water boiled | V32: g | W32: =((AA12-$N15)*(AA8-W8)/($N$20-W8)+(AA13-$N16)*(AA9-W9)/($N$20-W9)+(AA14-$N17)*(AA10-W10)/($N$20-W10)+(AA15-$N18)*(AA11-W11)/($N$20-W11)) -> #DIV/0! | X32: wcr | AA32: =((AI12-$N15)*(AI8-AE8)/($N$20-AE8)+(AI13-$N16)*(AI9-AE9)/($N$20-AE9)+(AI14-$N17)*(AI10-AE10)/($N$20-AE10)+(AI15-$N18)*(AI11-AE11)/($N$20-AE11)) -> #DIV/0! | AB32: whr | AE32: Water remaining at end - All Pots | AM32: g | AP32: =(AP12-$N$15+((AP9-25)/(N20-25))*(AP13-N16)+((AP10-25)/(N20-25))*(AP14-N17)+((AP11-25)/(N20-25))*(AP15-N18)) -> 0 | AQ32: wsr
U33: Time to boil Pot # 1 | V33: min | W33: =(AA6-W6)*1440 -> 0 | X33: Δtc | AA33: =(AI6-AE6)*1440 -> 0 | AB33: Δth | AE33: Time of simmer (should be ~45 minutes) | AM33: min | AP33: =(AP6-AL6)*1440 -> 0 | AQ33: Δts
U34: Temp-corr time to boil Pot # 1 | V34: min | W34: =W33*75/(N20-W8) -> #DIV/0! | X34: ΔtTc | AA34: =AA33*75/(N20-AE8) -> #DIV/0! | AB34: ΔtTh | AE34: Thermal efficiency | AM34: % | AP34: =(4.186*((AL12-$N15+AP32)/2)*(AP8-AL8)+2260*AP31)/(AP30*$E$20) -> #DIV/0! | AQ34: hs
U35: Thermal efficiency | V35: % | W35: =(4.186*SUM((W12-$N15)*(AA8-W8),(W13-$N16)*(AA9-W9),(W14-$N17)*(AA10-W10),(W15-$N18)*(AA11-W11))+2260*W31)/(W30*$E20) -> #DIV/0! | X35: hc | AA35: =(4.186*SUM((AE12-$N15)*(AI8-AE8),(AE13-$N16)*(AI9-AE9),(AE14-$N17)*(AI10-AE10),(AE15-$N18)*(AI11-AE11))+2260*AA31)/(AA30*$E20) -> #DIV/0! | AB35: hh | AE35: Burning rate | AM35: g/min | AP35: =AP30/AP33 -> #DIV/0! | AQ35: rsb
B36: BASIC TEST DATA | U36: Burning rate | V36: g/min | W36: =W30/W33 -> #DIV/0! | X36: rcb | AA36: =AA30/AA33 -> #DIV/0! | AB36: rhb | AE36: Specific fuel consumption | AM36: g/liter remaining | AP36: =AP30/AP32*1000 -> #DIV/0! | AQ36: SCs
U37: Specific fuel consumption | V37: g/liter boiled | W37: =1000*W30/W32 -> #DIV/0! | X37: SCc | AA37: =1000*AA30/AA32 -> #DIV/0! | AB37: SCh | AE37: Firepower | AM37: watts | AP37: =AP30*$E$20/(AP33*60) -> #DIV/0! | AQ37: FPs
B38: ="TEST #6 "&D7 -> TEST #6 | U38: Temp-corr sp consumption | V38: g/liter | W38: =W37*75/($N$20-W8) -> #DIV/0! | X38: SCTc | AA38: =AA37*75/($N$20-AE8) -> #DIV/0! | AB38: SCTh | AE38: Turn down ratio | AM38: -- | AP38: =W40/AP37 -> #DIV/0! | AQ38: TDR
B39: Notes on the High Power - Cold Start Test. Add description only if it differs from "General Information" sheet | U39: Temp-corr sp energy consumpt. | V39: kJ/liter | W39: =(W38/1000)*E20 -> #DIV/0! | X39: SETC | AA39: =(AA38/1000)*E20 -> #DIV/0! | AB39: SETH | AE39: Specific Energy Consumption | AM39: kJ/liter | AP39: =(AP36/1000)*E20 -> #DIV/0! | AQ39: SES
U40: Firepower | V40: watts | W40: =W30*$E$20/(W33*60) -> #DIV/0! | X40: FPc | AA40: =AA30*$E$20/(AA33*60) -> #DIV/0! | AB40: FPh | AE40: Fuel Benchmark to Complete 5L WBT | AM40: g | AP40: =IF(ISERROR(AA38),5*(W38+AP36),5*(AVERAGE(W38,AA38)+AP36)) -> #DIV/0! | AQ40: BF
AE41: Energy Benchmark to Complete 5L WBT | AM41: kJ | AP41: =(AP40/1000)*E20 -> #DIV/0! | AQ41: BE
...

Sheet Test-7
A2: ="WATER BOILING TEST - VERSION "&version&" - TEST #7" -> WATER BOILING TEST - VERSION 4.2.3 - TEST #7 | U2: ="TEST #7 "&D7 -> TEST #7 | W2: COLD START HIGH POWER | AE2: HOT START HIGH POWER (OPTIONAL) | AL2: SIMMER TEST
B3: DATA AND CALCULATION FORM (for one to four pots)* | W3: Start | AA3: Finish: when | AE3: Start | AI3: Finish: when | AL3: Start | AP3: Finish: 45 min
B4: Shaded cells and arrows require user input; unshaded cells automatically display outputs | AA4: Pot #1 boils | AI4: Pot #1 boils
B5: Qualitative data | U5: Measurements | V5: Units | W5: data | X5: label | AA5: data | AB5: label | AE5: data | AF5: label | AI5: data | AJ5: label | AL5: data | AM5: label | AP5: data | AQ5: label
B6: Name(s) of Tester(s) | M6: gray: efficiency | U6: Time (in 24 hour form) | V6: hr:min | X6: tci | AB6: tcf | AF6: thi | AJ6: thf | AM6: tsi | AQ6: tsf
B7: Test Number | M7: blue: emissions | U7: Weight of fuel | V7: g | X7: fci | AB7: fcf | AF7: fhi | AJ7: fhf | AM7: fsi | AQ7: fsf
B8: Date | M8: pink: error, missing input | U8: Water temperature, Pot # 1 | V8: ºC | X8: T1ci | AB8: T1cf | AF8: T1hi | AJ8: T1hf | AM8: T1si | AQ8: T1sf
B9: Location | D9: ='General Information'!C7 -> 0 | U9: Water temperature, Pot # 2 | V9: ºC | X9: T2ci | AB9: T2cf | AF9: T2hi | AJ9: T2hf | AM9: T2si | AQ9: T2sf
B10: Stove type/model | D10: ='General Information'!C10 -> 0 | U10: Water temperature, Pot # 3 | V10: ºC | X10: T3ci | AB10: T3cf | AF10: T3hi | AJ10: T3hf | AM10: T3si | AQ10: T3sf
B11: Type of fuel | D11: ='General Information'!J3 -> 0 | U11: Water temperature, Pot # 4 | V11: ºC | X11: T4ci | AB11: T4cf | AF11: T4hi | AJ11: T4hf | AM11: T4si | AQ11: T4sf
U12: Weight of Pot # 1 with water | V12: g | X12: P1ci | AB12: P1cf | AF12: P1hi | AJ12: P1hf | AM12: P1si | AQ12: P1sf
B13: Initial Test Conditions | U13: Weight of Pot # 2 with water | V13: g | X13: P2ci | AB13: P2cf | AF13: P2hi | AJ13: P2hf | AM13: P2si | AQ13: P2sf
B14: Data | E14: value | G14: units | I14: label | K14: Data | N14: value | P14: units | R14: label | U14: Weight of Pot # 3 with water | V14: g | X14: P3ci | AB14: P3cf | AF14: P3hi | AJ14: P3hf | AM14: P3si | AQ14: P3sf
B15: Air temperature | G15: ºC | K15: Dry weight of Pot # 1 (grams) | P15: g | R15: P1 | U15: Weight of Pot # 4 with water | V15: g | X15: P4ci | AB15: P4cf | AF15: P4hi | AJ15: P4hf | AM15: P4si | AQ15: P4sf
B16: Wind conditions | E16: 1 | K16: Dry weight of Pot # 2 (grams) | P16: g | R16: P2 | U16: Fire-starting materials (if any) | V16: --
B17: Fuel dimensions | K17: Dry weight of Pot # 3 (grams) | P17: g | R17: P3 | U17: Weight of charcoal+container | V17: g | AB17: cc | AI17: =AA17 -> 0 | AJ17: ch | AQ17: cs
B18: Fuel moisture content (wet basis) | G18: % | I18: MC | K18: Dry weight of Pot # 4 (grams) | P18: g | R18: P4 | U18: Average CO2 | V18: ppm | AB18: CO2c | AJ18: CO2h | AQ18: CO2s
B19: Gross calorific value (dry fuel) | E19: ='General Information'!L21 -> 0 | G19: kJ/kg | I19: HHV | K19: Weight of container for char (grams) | P19: g | R19: k | U19: Average CO | V19: ppm | Z19: 10 | AB19: COc | AJ19: COh | AQ19: COs
B20: Net calorific value (dry fuel) | E20: ='General Information'!L22 -> 0 | G20: kJ/kg | I20: LHV | K20: Local boiling point | N20: ='General Information'!C20 -> 0 | P20: ºC | R20: Tb | U20: Average PM | V20: ug/m3 | AB20: PMc | AJ20: PMh | AQ20: PMs
B21: Effective calorific value | K21: Background concentrations: CO2 | P21: ppm | R21: CO2,b | U21: Average Duct Temperature | V21: ºC | AB21: Tcd | AJ21: Thd | AQ21: Tsd
B22: (accounting for fuel moisture) | E22: =E20*(1-E18)-(E18*((N20-E15)*4.2+2260)) -> 0 | G22: kJ/kg | I22: EHV | M22: CO | P22: ppm | R22: CO,b | U22: Total CO2 (if available) | V22: g | AB22: mCO2,c | AJ22: mCO2,h | AQ22: mCO2,s
B23: Char calorific value | E23: ='General Information'!L11 -> 0 | G23: kJ/kg | M23: PM | P23: ug/m3 | R23: PM,b | U23: Total CO (if available) | V23: g | Z23: 10 | AB23: mCO,c | AJ23: mCO,h | AQ23: mCO,s
U24: Total PM (if available) | V24: g | AB24: mPM,c | AJ24: mPM,h | AQ24: mPM,s
B25: Notes about this test:
W26: COLD START | AA26: HOT START | AE26: SIMMER TEST (CALCULATIONS DIFFER FROM HIGH POWER TEST)
U27: Calculations/Results | V27: Units | W27: data | X27: label | AA27: data | AB27: label | AE27: Calculations/Results | AM27: Units | AP27: data | AQ27: label
U28: Fuel consumed (moist) | V28: g | W28: =W7-AA7 -> 0 | X28: fcm | AA28: =AE7-AI7 -> 0 | AB28: fhm | AE28: Fuel consumed during the simmer phase (moist) | AM28: g | AP28: =AL7-AP7 -> 0 | AQ28: fsm
U29: Net change in char during test | V29: g | W29: =AA17-$N$19 -> 0 | X29: Δcc | AA29: =IF(AA28=0,0,AI17-$N$19) -> 0 | AB29: Δch | AE29: Net change in char during test phase | AM29: g | AP29: =(AP17-$N$19)-W29 -> 0 | AQ29: Δcs
U30: Equivalent dry fuel consumed | V30: g | W30: =(W28*($E$20*(1-$E$18)-$E$18*(4.186*($N$20-$E$15)+2257))-W29*$E23)/$E$20 -> #DIV/0! | X30: fcd | AA30: =IF(AA28=0,0,(AA28*($E$20*(1-$E$18)-$E$18*(4.186*($N$20-$E$15)+2257))-AA29*$E23)/$E$20) -> 0 | AB30: fhd | AE30: Equivalent dry fuel consumed | AM30: g | AP30: =(AP28*($E$20*(1-$E$18)-$E$18*(4.186*($N$20-$E$15)+2257))-AP29*$E23)/$E$20 -> #DIV/0! | AQ30: fsd
U31: Water vaporized from all pots | V31: g | W31: =SUM(W12:W15)-SUM(AA12:AA15) -> 0 | X31: wcv | AA31: =SUM(AE12:AE15)-SUM(AI12:AI15) -> 0 | AB31: whv | AE31: Water vaporized | AM31: g | AP31: =(AL12-AP12)+(AL13-AP13)+(AL14-AP14)+(AL15-AP15) -> 0 | AQ31: wsv
